C:\Users\darea\Downloads\UltimateDiscordAssistant (2)\UltimateDiscordAssistant>heroku logs --tail -a trrr-bot
2025-06-01T16:16:05.100838+00:00 app[worker.1]: ERROR:discord.app_commands.tree:Ignoring exception in command 'purge'
2025-06-01T16:16:05.100852+00:00 app[worker.1]: Traceback (most recent call last):
2025-06-01T16:16:05.100853+00:00 app[worker.1]: File "/app/.heroku/python/lib/python3.11/site-packages/discord/app_commands/commands.py", line 857, in _do_call
2025-06-01T16:16:05.100855+00:00 app[worker.1]: return await self._callback(self.binding, interaction, **params)  # type: ignore
2025-06-01T16:16:05.100856+00:00 app[worker.1]: ^^^^^^^^^^^^^^^^^^^^^^^^^^^^^^^^^^^^^^^^^^^^^^^^^^^^^^^^^
2025-06-01T16:16:05.100856+00:00 app[worker.1]: File "/app/cogs/moderation_advanced.py", line 365, in purge_messages
2025-06-01T16:16:05.100857+00:00 app[worker.1]: await interaction.response.defer(ephemeral=True)
2025-06-01T16:16:05.100858+00:00 app[worker.1]: File "/app/.heroku/python/lib/python3.11/site-packages/discord/interactions.py", line 844, in defer
2025-06-01T16:16:05.100859+00:00 app[worker.1]: response = await adapter.create_interaction_response(
2025-06-01T16:16:05.100859+00:00 app[worker.1]: ^^^^^^^^^^^^^^^^^^^^^^^^^^^^^^^^^^^^^^^^^^
2025-06-01T16:16:05.100859+00:00 app[worker.1]: File "/app/.heroku/python/lib/python3.11/site-packages/discord/webhook/async_.py", line 224, in request
2025-06-01T16:16:05.100859+00:00 app[worker.1]: raise NotFound(response, data)
2025-06-01T16:16:05.100860+00:00 app[worker.1]: discord.errors.NotFound: 404 Not Found (error code: 10062): Unknown interaction
2025-06-01T16:16:05.100861+00:00 app[worker.1]:
2025-06-01T16:16:05.100861+00:00 app[worker.1]: The above exception was the direct cause of the following exception:
2025-06-01T16:16:05.100862+00:00 app[worker.1]:
2025-06-01T16:16:05.100862+00:00 app[worker.1]: Traceback (most recent call last):
2025-06-01T16:16:05.100862+00:00 app[worker.1]: File "/app/.heroku/python/lib/python3.11/site-packages/discord/app_commands/tree.py", line 1310, in _call
2025-06-01T16:16:05.100863+00:00 app[worker.1]: await command._invoke_with_namespace(interaction, namespace)
2025-06-01T16:16:05.100863+00:00 app[worker.1]: File "/app/.heroku/python/lib/python3.11/site-packages/discord/app_commands/commands.py", line 883, in _invoke_with_namespace
2025-06-01T16:16:05.100864+00:00 app[worker.1]: return await self._do_call(interaction, transformed_values)
2025-06-01T16:16:05.100864+00:00 app[worker.1]: ^^^^^^^^^^^^^^^^^^^^^^^^^^^^^^^^^^^^^^^^^^^^^^^^^^^^
2025-06-01T16:16:05.100864+00:00 app[worker.1]: File "/app/.heroku/python/lib/python3.11/site-packages/discord/app_commands/commands.py", line 876, in _do_call
2025-06-01T16:16:05.100865+00:00 app[worker.1]: raise CommandInvokeError(self, e) from e
2025-06-01T16:16:05.100866+00:00 app[worker.1]: discord.app_commands.errors.CommandInvokeError: Command 'purge' raised an exception: NotFound: 404 Not Found (error code: 10062): Unknown interaction
2025-06-01T16:17:40.670892+00:00 app[worker.1]: ERROR:discord.app_commands.tree:Ignoring exception in command 'join'
2025-06-01T16:17:40.670900+00:00 app[worker.1]: Traceback (most recent call last):
2025-06-01T16:17:40.670900+00:00 app[worker.1]: File "/app/.heroku/python/lib/python3.11/site-packages/discord/app_commands/commands.py", line 857, in _do_call
2025-06-01T16:17:40.670938+00:00 app[worker.1]: return await self._callback(self.binding, interaction, **params)  # type: ignore
2025-06-01T16:17:40.670938+00:00 app[worker.1]: ^^^^^^^^^^^^^^^^^^^^^^^^^^^^^^^^^^^^^^^^^^^^^^^^^^^^^^^^^
2025-06-01T16:17:40.670938+00:00 app[worker.1]: File "/app/cogs/music_premium.py", line 97, in join_voice
2025-06-01T16:17:40.670939+00:00 app[worker.1]: await channel.connect()
2025-06-01T16:17:40.670939+00:00 app[worker.1]: File "/app/.heroku/python/lib/python3.11/site-packages/discord/abc.py", line 1984, in connect
2025-06-01T16:17:40.670939+00:00 app[worker.1]: voice: T = cls(client, self)
2025-06-01T16:17:40.670939+00:00 app[worker.1]: ^^^^^^^^^^^^^^^^^
2025-06-01T16:17:40.670940+00:00 app[worker.1]: File "/app/.heroku/python/lib/python3.11/site-packages/discord/voice_client.py", line 220, in __init__
2025-06-01T16:17:40.670940+00:00 app[worker.1]: raise RuntimeError("PyNaCl library needed in order to use voice")
2025-06-01T16:17:40.670941+00:00 app[worker.1]: RuntimeError: PyNaCl library needed in order to use voice
2025-06-01T16:17:40.670941+00:00 app[worker.1]:
2025-06-01T16:17:40.670941+00:00 app[worker.1]: The above exception was the direct cause of the following exception:
2025-06-01T16:17:40.670941+00:00 app[worker.1]:
2025-06-01T16:17:40.670942+00:00 app[worker.1]: Traceback (most recent call last):
2025-06-01T16:17:40.670942+00:00 app[worker.1]: File "/app/.heroku/python/lib/python3.11/site-packages/discord/app_commands/tree.py", line 1310, in _call
2025-06-01T16:17:40.670942+00:00 app[worker.1]: await command._invoke_with_namespace(interaction, namespace)
2025-06-01T16:17:40.670942+00:00 app[worker.1]: File "/app/.heroku/python/lib/python3.11/site-packages/discord/app_commands/commands.py", line 883, in _invoke_with_namespace
2025-06-01T16:17:40.670942+00:00 app[worker.1]: return await self._do_call(interaction, transformed_values)
2025-06-01T16:17:40.670943+00:00 app[worker.1]: ^^^^^^^^^^^^^^^^^^^^^^^^^^^^^^^^^^^^^^^^^^^^^^^^^^^^
2025-06-01T16:17:40.670943+00:00 app[worker.1]: File "/app/.heroku/python/lib/python3.11/site-packages/discord/app_commands/commands.py", line 876, in _do_call
2025-06-01T16:17:40.670943+00:00 app[worker.1]: raise CommandInvokeError(self, e) from e
2025-06-01T16:17:40.670945+00:00 app[worker.1]: discord.app_commands.errors.CommandInvokeError: Command 'join' raised an exception: RuntimeError: PyNaCl library needed in order to use voice
2025-06-01T16:17:57.814753+00:00 app[worker.1]: ERROR:discord.app_commands.tree:Ignoring exception in command 'play'
2025-06-01T16:17:57.814763+00:00 app[worker.1]: Traceback (most recent call last):
2025-06-01T16:17:57.814765+00:00 app[worker.1]: File "/app/.heroku/python/lib/python3.11/site-packages/discord/app_commands/tree.py", line 1310, in _call
2025-06-01T16:17:57.814765+00:00 app[worker.1]: await command._invoke_with_namespace(interaction, namespace)
2025-06-01T16:17:57.814766+00:00 app[worker.1]: File "/app/.heroku/python/lib/python3.11/site-packages/discord/app_commands/commands.py", line 882, in _invoke_with_namespace
2025-06-01T16:17:57.814767+00:00 app[worker.1]: transformed_values = await self._transform_arguments(interaction, namespace)
2025-06-01T16:17:57.814767+00:00 app[worker.1]: ^^^^^^^^^^^^^^^^^^^^^^^^^^^^^^^^^^^^^^^^^^^^^^^^^^^^^^^
2025-06-01T16:17:57.814768+00:00 app[worker.1]: File "/app/.heroku/python/lib/python3.11/site-packages/discord/app_commands/commands.py", line 846, in _transform_arguments
2025-06-01T16:17:57.814769+00:00 app[worker.1]: raise CommandSignatureMismatch(self) from None
2025-06-01T16:17:57.814770+00:00 app[worker.1]: discord.app_commands.errors.CommandSignatureMismatch: The signature for command 'play' is different from the one provided by Discord. This can happen because either your code is out of date or you have not synced the commands with Discord, causing the mismatch in data. It is recommended to sync the command tree to fix this issue.
2025-06-01T16:18:21.519095+00:00 app[worker.1]: ERROR:discord.app_commands.tree:Ignoring exception in command 'play'
2025-06-01T16:18:21.519116+00:00 app[worker.1]: Traceback (most recent call last):
2025-06-01T16:18:21.519126+00:00 app[worker.1]: File "/app/.heroku/python/lib/python3.11/site-packages/discord/app_commands/tree.py", line 1310, in _call
2025-06-01T16:18:21.519126+00:00 app[worker.1]: await command._invoke_with_namespace(interaction, namespace)
2025-06-01T16:18:21.519126+00:00 app[worker.1]: File "/app/.heroku/python/lib/python3.11/site-packages/discord/app_commands/commands.py", line 882, in _invoke_with_namespace
2025-06-01T16:18:21.519127+00:00 app[worker.1]: transformed_values = await self._transform_arguments(interaction, namespace)
2025-06-01T16:18:21.519127+00:00 app[worker.1]: ^^^^^^^^^^^^^^^^^^^^^^^^^^^^^^^^^^^^^^^^^^^^^^^^^^^^^^^
2025-06-01T16:18:21.519127+00:00 app[worker.1]: File "/app/.heroku/python/lib/python3.11/site-packages/discord/app_commands/commands.py", line 846, in _transform_arguments
2025-06-01T16:18:21.519128+00:00 app[worker.1]: raise CommandSignatureMismatch(self) from None
2025-06-01T16:18:21.519128+00:00 app[worker.1]: discord.app_commands.errors.CommandSignatureMismatch: The signature for command 'play' is different from the one provided by Discord. This can happen because either your code is out of date or you have not synced the commands with Discord, causing the mismatch in data. It is recommended to sync the command tree to fix this issue.
2025-06-01T16:18:50.685763+00:00 app[worker.1]: ERROR:discord.app_commands.tree:Ignoring exception in command 'play'
2025-06-01T16:18:50.685775+00:00 app[worker.1]: Traceback (most recent call last):
2025-06-01T16:18:50.685776+00:00 app[worker.1]: File "/app/.heroku/python/lib/python3.11/site-packages/discord/app_commands/tree.py", line 1310, in _call
2025-06-01T16:18:50.685776+00:00 app[worker.1]: await command._invoke_with_namespace(interaction, namespace)
2025-06-01T16:18:50.685777+00:00 app[worker.1]: File "/app/.heroku/python/lib/python3.11/site-packages/discord/app_commands/commands.py", line 882, in _invoke_with_namespace
2025-06-01T16:18:50.685777+00:00 app[worker.1]: transformed_values = await self._transform_arguments(interaction, namespace)
2025-06-01T16:18:50.685777+00:00 app[worker.1]: ^^^^^^^^^^^^^^^^^^^^^^^^^^^^^^^^^^^^^^^^^^^^^^^^^^^^^^^
2025-06-01T16:18:50.685778+00:00 app[worker.1]: File "/app/.heroku/python/lib/python3.11/site-packages/discord/app_commands/commands.py", line 846, in _transform_arguments
2025-06-01T16:18:50.685779+00:00 app[worker.1]: raise CommandSignatureMismatch(self) from None
2025-06-01T16:18:50.685784+00:00 app[worker.1]: discord.app_commands.errors.CommandSignatureMismatch: The signature for command 'play' is different from the one provided by Discord. This can happen because either your code is out of date or you have not synced the commands with Discord, causing the mismatch in data. It is recommended to sync the command tree to fix this issue.
2025-06-01T16:19:05.922019+00:00 app[worker.1]: ERROR:discord.app_commands.tree:Ignoring exception in command 'play'
2025-06-01T16:19:05.922055+00:00 app[worker.1]: Traceback (most recent call last):
2025-06-01T16:19:05.922056+00:00 app[worker.1]: File "/app/.heroku/python/lib/python3.11/site-packages/discord/app_commands/tree.py", line 1310, in _call
2025-06-01T16:19:05.922056+00:00 app[worker.1]: await command._invoke_with_namespace(interaction, namespace)
2025-06-01T16:19:05.922057+00:00 app[worker.1]: File "/app/.heroku/python/lib/python3.11/site-packages/discord/app_commands/commands.py", line 882, in _invoke_with_namespace
2025-06-01T16:19:05.922057+00:00 app[worker.1]: transformed_values = await self._transform_arguments(interaction, namespace)
2025-06-01T16:19:05.922057+00:00 app[worker.1]: ^^^^^^^^^^^^^^^^^^^^^^^^^^^^^^^^^^^^^^^^^^^^^^^^^^^^^^^
2025-06-01T16:19:05.922058+00:00 app[worker.1]: File "/app/.heroku/python/lib/python3.11/site-packages/discord/app_commands/commands.py", line 846, in _transform_arguments
2025-06-01T16:19:05.922058+00:00 app[worker.1]: raise CommandSignatureMismatch(self) from None
2025-06-01T16:19:05.922059+00:00 app[worker.1]: discord.app_commands.errors.CommandSignatureMismatch: The signature for command 'play' is different from the one provided by Discord. This can happen because either your code is out of date or you have not synced the commands with Discord, causing the mismatch in data. It is recommended to sync the command tree to fix this issue.
2025-06-01T16:19:59.819293+00:00 app[worker.1]: ERROR:discord.app_commands.tree:Ignoring exception in command 'play'
2025-06-01T16:19:59.819305+00:00 app[worker.1]: Traceback (most recent call last):
2025-06-01T16:19:59.819316+00:00 app[worker.1]: File "/app/.heroku/python/lib/python3.11/site-packages/discord/app_commands/tree.py", line 1310, in _call
2025-06-01T16:19:59.819316+00:00 app[worker.1]: await command._invoke_with_namespace(interaction, namespace)
2025-06-01T16:19:59.819317+00:00 app[worker.1]: File "/app/.heroku/python/lib/python3.11/site-packages/discord/app_commands/commands.py", line 882, in _invoke_with_namespace
2025-06-01T16:19:59.819319+00:00 app[worker.1]: transformed_values = await self._transform_arguments(interaction, namespace)
2025-06-01T16:19:59.819329+00:00 app[worker.1]: ^^^^^^^^^^^^^^^^^^^^^^^^^^^^^^^^^^^^^^^^^^^^^^^^^^^^^^^
2025-06-01T16:19:59.819329+00:00 app[worker.1]: File "/app/.heroku/python/lib/python3.11/site-packages/discord/app_commands/commands.py", line 846, in _transform_arguments
2025-06-01T16:19:59.819330+00:00 app[worker.1]: raise CommandSignatureMismatch(self) from None
2025-06-01T16:19:59.819332+00:00 app[worker.1]: discord.app_commands.errors.CommandSignatureMismatch: The signature for command 'play' is different from the one provided by Discord. This can happen because either your code is out of date or you have not synced the commands with Discord, causing the mismatch in data. It is recommended to sync the command tree to fix this issue.
